Workbook

Sheet README
A1: Categorie are:
A2: 1.⁠ ⁠Gender-based (G) : jokes targeting gender roles, or gender features.
A3: 2.⁠ ⁠Racial/Ethnic (RE): jokes targeting race, nationality, or ethnicity.
A4: 3.⁠ ⁠Age-based (Age): jokes targeting age groups
A5: 4.⁠ ⁠Appearance/Physical condition (AP): jokes targeting looks, body type, or any disabilities or diseases.
A6: 5.⁠ ⁠Religion-based (R): jokes targeting religious groups or beliefs.
A7: 6.⁠ ⁠Class/Occupation (CO): jokes targeting professions or socioeconomic class.
A8: 7. Sexual orientation (S): jokes targeting LGBTQ+ identities.
A9: 8. Political/Ideological (PI): jokes targeting political figures, parties, or ideological groups.
A10: 9. Mental health (M): jokes targeting mental illness or psychological conditions.
A11: 10. None (N): No categories between those, or more than one
A13: You can use the code to simplify the labelling
... A17: Here is who does what:
A19: Sheet | B19: Annotator | C19: Adjudicator
A20: sample_1a | B20: Millan
A21: sample_1b | B21: Mathias
A22: conflict_1 | C22: Alice
A23: sample_2a | B23: Alice
A24: sample_2b | B24: Zuzana
A25: conflict_2 | C25: Barthélemy
A26: sample_3a | B26: Barthélemy
A27: sample_3b | B27: Millan
A28: conflict_3 | C28: Mathias
A29: sample_4a | B29: Mathias
A30: sample_4b | B30: Zuzana
A31: conflict_4 | C31: Millan
A32: sample_5a | B32: Alice
A33: sample_5b | B33: Barthélemy
A34: conflict_5 | C34: Zuzana

Sheet sample_1a
A1: id | B1: joke | C1: category_human
A2: 1 | B2: The best way to catch a Bear.. First you gotta dig a hole just big enough that the bear won't be able to climb it's way out. Then along the edges you put berries and other things bears eat and once you've done that you fill the hole in with ash. So once the bear comes up and starts to eat the berries you sneak behind him and kick him in the ash hole. | C2: N
A3: 2 | B3: What do you call a domineering pill bug? A controly-poly! | C3: N
A4: 3 | B4: What do you call someone whose filed bankruptcy 4 times and divorced twice? A GOP Presidential candidate. | C4: PI
A5: 4 | B5: Some girl told me today I was odd, I can't even... | C5: N
A6: 5 | B6: What did the pirate say on his eightieth birthday? Aye, Matey! | C6: N
A7: 6 | B7: What do you call a woman who smuggles things inside her? A cuntainer. | C7: G
A8: 7 | B8: I searched dirty jokes in google to repost on r/jokes My face popped up as the first result. | C8: M
A9: 8 | B9: where's the only living gay Saudi Arabian? just over a stones throw away | C9: S
A10: 9 | B10: I've heard all the Pro life vs Pro choice debates, and after hearing the debates, i came up with a compromise. I propose Pro Abortion, in which we abort everybody. | C10: R
A11: 10 | B11: My penis is only 4 inches... ...but I find most girls don't like it that wide. | C11: G
A12: 11 | B12: Abdul writes to his son Ahmed "Dear Ahmed," so goes the letter. "I want to plant some vegetables in my garden so that we can have some home-grown food in the winter. But you know how bad my back is. Could you please come visit me and help me with it?" The reply comes soon. "Father, I am sorry but I am preoccupied with work, so I can't help. And I'm not sure we should be digging up your garden, because as I recall, my friend Amir hid *the thing* there." The very next day, security services show up at Abdul's home, check every nook and cranny, cause the old man quite a fright, but eventually, finding nothing, they leave. Abdul, distressed, writes back to Ahmed. "Dear Ahmed! A bunch of guys in black suits showed up today, trampled mud all over the house, and poked their nose into everything they could find! They left and let me go, but what was that all about?" And the reply "Father; they dug up the garden too, haven't they? You can plant your vegetables now. Again, I am sorry I could not help otherwise, but I'll make it up to you with my potato salad that you like so much. Love, Ahmed." | C12: N, RE
A13: 12 | B13: Give a man a jacket... And he'll be able to leave the house. Teach a man to jacket, and he'll never leave the house. | C13: G
... A54: 53 | B54: Chung Hoi A famous American golfer is invited to go to China for a golfing tournament. From the second he gets there, he is treated like a king. He is given five-star treatment in a five-star hotel until the day of the tournament. The night before the tournament, he is sitting in his hotel room watching TV. A hot Asian girl walks up to his room and he says, "Wow. They must really love me here." He begins to have sex with her the whole night. She continues to scream, "Chung Hoi! Chung Hoi!," but he ignores it. At the tournament, the American golfer gets a hole-in-one and gets really excited. He starts yelling, "Chung Hoi! Chung Hoi!" One of the Chinese golfers says, "What do you mean 'WRONG HOLE'?" | C54: RE
A55: 54 | B55: A guy’s driving down the highway one day... ... when he sees a hitchhiker ahead. There’s hardly any traffic on the highway, and he figures that the poor guy will never get a ride, so he decides to help him out. After about 5 miles, the hitchhiker pulls a gun, and tells the driver that he won’t get hurt as long as he follows orders and doesn’t try anything stupid. The hitcher has the driver pull over and stop the car. “I just broke out of jail, and I need to get as far away from here as I can.” He makes the driver strip naked, ties his wrists to his ankles, and pushes him down a small ravine, just enough to waste some time getting back up. When the driver makes it to the side of the road, there’s no traffic. He’s so frustrated he’s about to cry. Then he sees a semi truck rolling down the road his way. Still tied up, he jumps up and down to be seen, and sure enough the truck pulls over. The trucker asks, “Well what happened to you?” The ex-driver says, “Some guy pulled a gun on me, tied me up like this and stole my car!” The trucker shakes his head as he starts to unzip his pants, smiles and says, “Son, it just ain’t your day, is it?”
A56: 55 | B56: Why didn't Pluto organise his birthday party? He couldn't planet. | C56: N
A57: 56 | B57: After a thorough research and survey scientists claim that the thicker your thighs, The more snacks you can lay on your lap. | C57: G
A58: 57 | B58: I think I want to be a garbage man. I hear the industry is picking up! | C58: CO
A59: 58 | B59: Who is the commander of cheese? Sargento | C59: N
A60: 59 | B60: Why does the KKK wear all white? Because they hate black, people!!! | C60: RE
A61: 60 | B61: Took my computer to a repair shop. He said here's your problem. Someone put peanutbutter in the hard drive. | C61: N
A62: 61 | B62: Why do Jewish men get circumcised? Because Jewish women won't touch anything unless it's 20% off | C62: R, RE
A63: 62 | B63: My colleagues thought it would be good to each wear a shirt representing our star sign for our ‘make a wish foundation’ fundraiser Now I’m here wearing the word CANCER across my chest and feel a right knob | C63: Age, AP
A64: 63 | B64: Did you hear about the guy who plotted to severely scorch his friend by trying to burn him alive with one of his diplomas when the weather was as cold as the freezing point of water? At zero degree Celsius, he attempted first degree murder, using his second degree as kindling, resulting in third degree burns. | C64: N
A65: 64 | B65: I can't watch the Super Bowl this year. It's all a LI | C65: N
A66: 65 | B66: Why was Helen Keller a bad driver? She was a woman | C66: G
A67: 66 | B67: Best porn star name Queef Latina | C67: G, RE
... A101: 100 | B101: I love pteradons They're my favorite dinosoars. | C101: N

Sheet sample_1b
A1: id | B1: joke | C1: category_human
A2: 1 | B2: The best way to catch a Bear.. First you gotta dig a hole just big enough that the bear won't be able to climb it's way out. Then along the edges you put berries and other things bears eat and once you've done that you fill the hole in with ash. So once the bear comes up and starts to eat the berries you sneak behind him and kick him in the ash hole. | C2: N
A3: 2 | B3: What do you call a domineering pill bug? A controly-poly! | C3: N
A4: 3 | B4: What do you call someone whose filed bankruptcy 4 times and divorced twice? A GOP Presidential candidate. | C4: PI
A5: 4 | B5: Some girl told me today I was odd, I can't even... | C5: N
A6: 5 | B6: What did the pirate say on his eightieth birthday? Aye, Matey! | C6: N
A7: 6 | B7: What do you call a woman who smuggles things inside her? A cuntainer. | C7: G
A8: 7 | B8: I searched dirty jokes in google to repost on r/jokes My face popped up as the first result. | C8: AP
A9: 8 | B9: where's the only living gay Saudi Arabian? just over a stones throw away | C9: S;RE
A10: 9 | B10: I've heard all the Pro life vs Pro choice debates, and after hearing the debates, i came up with a compromise. I propose Pro Abortion, in which we abort everybody. | C10: N
A11: 10 | B11: My penis is only 4 inches... ...but I find most girls don't like it that wide. | C11: N
A12: 11 | B12: Abdul writes to his son Ahmed "Dear Ahmed," so goes the letter. "I want to plant some vegetables in my garden so that we can have some home-grown food in the winter. But you know how bad my back is. Could you please come visit me and help me with it?" The reply comes soon. "Father, I am sorry but I am preoccupied with work, so I can't help. And I'm not sure we should be digging up your garden, because as I recall, my friend Amir hid *the thing* there." The very next day, security services show up at Abdul's home, check every nook and cranny, cause the old man quite a fright, but eventually, finding nothing, they leave. Abdul, distressed, writes back to Ahmed. "Dear Ahmed! A bunch of guys in black suits showed up today, trampled mud all over the house, and poked their nose into everything they could find! They left and let me go, but what was that all about?" And the reply "Father; they dug up the garden too, haven't they? You can plant your vegetables now. Again, I am sorry I could not help otherwise, but I'll make it up to you with my potato salad that you like so much. Love, Ahmed." | C12: RE
A13: 12 | B13: Give a man a jacket... And he'll be able to leave the house. Teach a man to jacket, and he'll never leave the house. | C13: N
... A88: 87 | B88: The past few days summed up Pepsi: We just pulled the worst PR stunt of the year. United Airlines: Hold my beer. Sean Spicer: LEEEEEEEEEEROY JEEENKINS. | C88: N
A89: 88 | B89: What do you call a moile in the Harry Potter wizarding world? Professor Snip
A90: 89 | B90: My descent into the cannibalistic devouring of a South African Bishop Call 00 8 22... | C90: N
A91: 90 | B91: An blobfish walks into 1 bar. The bartender asks, "Why the saggy face?" It became sad, so it decided to go to another bar. The blobfish is asked "Why the saggy face?" again, so it decides to go to another bar. However, the blobfish slowly began to return to normal. When he had already visited 15 bars, he was back to normal. ----- **^Note:** ^bar ^as ^in ^atmospheric ^pressure | C91: N
A92: 91 | B92: C sections. They really take it out of you. | C92: G
A93: 92 | B93: What happens when you go inside in a snow suit? It melts. | C93: N
A94: 93 | B94: What do you call a woman that makes more money than her husband? A widow. | C94: G
A95: 94 | B95: A bear walks up to a rabbit and asks "Do you have a problem with shit getting stuck in your fur?" Asks BEAR. The rabbit looked taken back, "Uhh, No" So the bear wiped his ass on the rabbit. | C95: N
A96: 95 | B96: What do my existence and an unsharpened pencil have in common? They're both dull and pointless. | C96: N
A97: 96 | B97: I went to the cinema to see a really, really sad film. The guy behind me was just wailing. Half way through, a harpoon hit the back of my head. | C97: N
A98: 97 | B98: The Billy saga continues... Mrs. Teacher is upset at being out-foxed by lil' Billy. So she decides to get even. Next week she tells the kids to study reallllly hard, because she will ask a question on Friday, that if one of them can answer it, he/she will get to have next Monday absence. So they study real hard. Come Friday, the teacher says "All right class, here's my question. How many gallons of water are in the ocean?" As the kids have no answer, they disappointedly trudge home to do the weekend homework. Next week the teacher tells them the same thing. "Study reallllly hard, and if you answer my question you get Monday absence." So the class studies hard. Come Friday, the teacher asks "All right class, here's my question. How many blades of grass are on the earth?" Once again, the kids trudge home disappointed. This time, Billy grabs a bag of ping pong balls, spray paints them all black, puts the bag in his backpack and bides his time for next week. Same thing next week. Come Friday, the class waits on the teacher. She says "All right class, here's my question..." And BAM! Billy bursts his bag of ping pong balls and the fly everywhere! One hits the teacher in the face! She grabs it, looks at it and asks "OK, who is the one with the crazy black balls??" Billy jumps up and answers "Eddie Murphy, teacher! I'll see you Tuesday!" | C98: Age
A99: 98 | B99: How many flies does it take to screw in a lightbulb? Two, but how’d they get in there? | C99: N
A100: 99 | B100: Dirty jokes is like water... It’s not always clean. | C100: N
A101: 100 | B101: I love pteradons They're my favorite dinosoars. | C101: N

Sheet conflict_1
A1: id | B1: joke | C1: Conflict | D1: Adjudication
A2: 1 | B2: The best way to catch a Bear.. First you gotta dig a hole just big enough that the bear won't be able to climb it's way out. Then along the edges you put berries and other things bears eat and once you've done that you fill the hole in with ash. So once the bear comes up and starts to eat the berries you sneak behind him and kick him in the ash hole. | C2: =IF(sample_1a!C2<>sample_1b!C2, sample_1a!C2 & " ≠ " & sample_1b!C2, "")
A3: 2 | B3: What do you call a domineering pill bug? A controly-poly! | C3: =IF(sample_1a!C3<>sample_1b!C3, sample_1a!C3 & " ≠ " & sample_1b!C3, "")
A4: 3 | B4: What do you call someone whose filed bankruptcy 4 times and divorced twice? A GOP Presidential candidate. | C4: =IF(sample_1a!C4<>sample_1b!C4, sample_1a!C4 & " ≠ " & sample_1b!C4, "")
A5: 4 | B5: Some girl told me today I was odd, I can't even... | C5: =IF(sample_1a!C5<>sample_1b!C5, sample_1a!C5 & " ≠ " & sample_1b!C5, "")
A6: 5 | B6: What did the pirate say on his eightieth birthday? Aye, Matey! | C6: =IF(sample_1a!C6<>sample_1b!C6, sample_1a!C6 & " ≠ " & sample_1b!C6, "")
A7: 6 | B7: What do you call a woman who smuggles things inside her? A cuntainer. | C7: =IF(sample_1a!C7<>sample_1b!C7, sample_1a!C7 & " ≠ " & sample_1b!C7, "")
A8: 7 | B8: I searched dirty jokes in google to repost on r/jokes My face popped up as the first result. | C8: =IF(sample_1a!C8<>sample_1b!C8, sample_1a!C8 & " ≠ " & sample_1b!C8, "") -> M ≠ AP | D8: AP
A9: 8 | B9: where's the only living gay Saudi Arabian? just over a stones throw away | C9: =IF(sample_1a!C9<>sample_1b!C9, sample_1a!C9 & " ≠ " & sample_1b!C9, "") -> S ≠ S;RE | D9: N
A10: 9 | B10: I've heard all the Pro life vs Pro choice debates, and after hearing the debates, i came up with a compromise. I propose Pro Abortion, in which we abort everybody. | C10: =IF(sample_1a!C10<>sample_1b!C10, sample_1a!C10 & " ≠ " & sample_1b!C10, "") -> R ≠ N | D10: G
A11: 10 | B11: My penis is only 4 inches... ...but I find most girls don't like it that wide. | C11: =IF(sample_1a!C11<>sample_1b!C11, sample_1a!C11 & " ≠ " & sample_1b!C11, "") -> G ≠ N | D11: G
A12: 11 | B12: Abdul writes to his son Ahmed "Dear Ahmed," so goes the letter. "I want to plant some vegetables in my garden so that we can have some home-grown food in the winter. But you know how bad my back is. Could you please come visit me and help me with it?" The reply comes soon. "Father, I am sorry but I am preoccupied with work, so I can't help. And I'm not sure we should be digging up your garden, because as I recall, my friend Amir hid *the thing* there." The very next day, security services show up at Abdul's home, check every nook and cranny, cause the old man quite a fright, but eventually, finding nothing, they leave. Abdul, distressed, writes back to Ahmed. "Dear Ahmed! A bunch of guys in black suits showed up today, trampled mud all over the house, and poked their nose into everything they could find! They left and let me go, but what was that all about?" And the reply "Father; they dug up the garden too, haven't they? You can plant your vegetables now. Again, I am sorry I could not help otherwise, but I'll make it up to you with my potato salad that you like so much. Love, Ahmed." | C12: =IF(sample_1a!C12<>sample_1b!C12, sample_1a!C12 & " ≠ " & sample_1b!C12, "") -> N, RE ≠ RE | D12: RE
A13: 12 | B13: Give a man a jacket... And he'll be able to leave the house. Teach a man to jacket, and he'll never leave the house. | C13: =IF(sample_1a!C13<>sample_1b!C13, sample_1a!C13 & " ≠ " & sample_1b!C13, "") -> G ≠ N | D13: G
A14: 13 | B14: If you’ve never tried blindfolded archery, let me tell you... You don’t know what you’re missing. | C14: =IF(sample_1a!C14<>sample_1b!C14, sample_1a!C14 & " ≠ " & sample_1b!C14, "")
A15: 14 | B15: A young woman was rummaging through her grandmother’s belongings, and she came across a mysterious lamp. A young woman was rummaging through her grandmother’s belongings, and she came across a mysterious lamp. Upon rubbing the lamp, Rick Astley appeared before her and said, “I will give you three wishes.” She thought for a moment and said, “For my first wish I would like to end world hunger.” “An admirable request. Consider it granted!” Rick said. “For my second wish, I would like world peace.” “Ah, this is a very difficult request, but it has been done. And for your final request?” She thought for a moment and decided to make this a selfish wish. “As a movie buff, I would like a copy of every movie in the world in my own private collection.” The genie a bit taken back . . . . paused and said, “This I cannot do . . .” “Why!?” The women exclaimed. “ You can fix world hunger and end all wars, but you cannot complete this simple task?!” The Genie looked away and said, “I can, but your collection will not be complete . . . you see . . . I’m never gunna give you Up!” | C15: =IF(sample_1a!C15<>sample_1b!C15, sample_1a!C15 & " ≠ " & sample_1b!C15, "")
A16: 15 | B16: Racism is a lot like Nickelback... Its fun to joke about, but you never want to see it in person. | C16: =IF(sample_1a!C16<>sample_1b!C16, sample_1a!C16 & " ≠ " & sample_1b!C16, "")
A17: 16 | B17: Is it ok to be against a certain race? because I hate relays. | C17: =IF(sample_1a!C17<>sample_1b!C17, sample_1a!C17 & " ≠ " & sample_1b!C17, "")
A18: 17 | B18: What do you call a smiling Roman with a hair in his teeth? Gladiator. | C18: =IF(sample_1a!C18<>sample_1b!C18, sample_1a!C18 & " ≠ " & sample_1b!C18, "") -> RE, N ≠ RE | D18: RE
A19: 18 | B19: The restaurant Hooters is known for two things... ...boobs. | C19: =IF(sample_1a!C19<>sample_1b!C19, sample_1a!C19 & " ≠ " & sample_1b!C19, "")
A20: 19 | B20: A Roman walks into a bar and holds up two fingers. "Five beers, please." | C20: =IF(sample_1a!C20<>sample_1b!C20, sample_1a!C20 & " ≠ " & sample_1b!C20, "")
A21: 20 | B21: “Excuse me, sir, have you seen a police officer around?” “Excuse me, sir, have you seen a police officer around?” - “No, not a soul, actually.” - “Very good, now give me your wallet, watch and laptop!” | C21: =IF(sample_1a!C21<>sample_1b!C21, sample_1a!C21 & " ≠ " & sample_1b!C21, "")
A22: 21 | B22: Today I learned that the elevator was named after Darth Vader's little sister. Ele. Ele Vader. | C22: =IF(sample_1a!C22<>sample_1b!C22, sample_1a!C22 & " ≠ " & sample_1b!C22, "")
A23: 22 | B23: I met a beautiful girl down at the park today. Sparks flew, she fell at my feet, and we ended up having sex right there and then. I fucking love my new Taser. | C23: =IF(sample_1a!C23<>sample_1b!C23, sample_1a!C23 & " ≠ " & sample_1b!C23, "")
A24: 23 | B24: A man has been having sex with his wife in the dark for 30 years and she just found out he's been using a dildo. Wife: "Explain the dildo." Man: "Then Explain the kids." | C24: =IF(sample_1a!C24<>sample_1b!C24, sample_1a!C24 & " ≠ " & sample_1b!C24, "") -> N, G ≠ G | D24: G
A25: 24 | B25: What do you call a pair of dancing Jews? A Jewet. | C25: =IF(sample_1a!C25<>sample_1b!C25, sample_1a!C25 & " ≠ " & sample_1b!C25, "") -> R, RE ≠ RE | D25: RE
A26: 25 | B26: There are two kinds of people in this world: (1) Those who can extrapolate from incomplete data. | C26: =IF(sample_1a!C26<>sample_1b!C26, sample_1a!C26 & " ≠ " & sample_1b!C26, "")
A27: 26 | B27: What did the egg say to the boiling water? "I don't think I can get hard -- I just got laid this morning! | C27: =IF(sample_1a!C27<>sample_1b!C27, sample_1a!C27 & " ≠ " & sample_1b!C27, "")
A28: 27 | B28: Russian computer: Please enter password Me: Beef_stew Russian computer: Password not stroganoff | C28: =IF(sample_1a!C28<>sample_1b!C28, sample_1a!C28 & " ≠ " & sample_1b!C28, "") -> RE ≠ N | D28: RE
A29: 28 | B29: Teacher/Student **The teacher says:** Today, we're going to talk about the tenses. Now, if I say "I am beautiful," which tense is it? **The student says:** Obviously it's the past tense. | C29: =IF(sample_1a!C29<>sample_1b!C29, sample_1a!C29 & " ≠ " & sample_1b!C29, "") -> Age, CO ≠ N | D29: Age
A30: 29 | B30: The German Shepherd cover up... I found my German Shepherd, Hondo, with the neighbor's pet rabbit in its mouth. The rabbit was dead, and I panicked.. I took the dirty, chewed-up rabbit into the house. I gave it a bath, blew dried its fur, and put it back into the cage at the neighbor's house, hoping they would think it died of natural causes. A few days later, the neighbor asked me, "Don, did you hear that Fluffy died?" I said, "Um... no... what happened?" The neighbor replied, "We found him dead in his cage one day, but the weird thing is that the day after we buried him, someone had dug him up, gave him a bath, and put him back into the cage. There are some real sick people out there!" | C30: =IF(sample_1a!C30<>sample_1b!C30, sample_1a!C30 & " ≠ " & sample_1b!C30, "")
A31: 30 | B31: What's the most powerful country after USA ? USB. | C31: =IF(sample_1a!C31<>sample_1b!C31, sample_1a!C31 & " ≠ " & sample_1b!C31, "")
A32: 31 | B32: You’re calling from inside one of the cartels?? "Yes, they wanted me to go with them" -Are you kidnapped? "Actually…No. I’m grownapped" -Have they hurt you in any way? "No. They just abduct-taped me" | C32: =IF(sample_1a!C32<>sample_1b!C32, sample_1a!C32 & " ≠ " & sample_1b!C32, "")
A33: 32 | B33: A confused Chinese student asks his master, "Master Shi, why do all Chinese look the same?" Then the master replied, "I am not master Shi." | C33: =IF(sample_1a!C33<>sample_1b!C33, sample_1a!C33 & " ≠ " & sample_1b!C33, "")
A34: 33 | B34: I baked a dog shaped dough in a local baking competition It was pure-bread. | C34: =IF(sample_1a!C34<>sample_1b!C34, sample_1a!C34 & " ≠ " & sample_1b!C34, "")
A35: 34 | B35: A boy brags to his friends that he just lost his virginity... A boy came running in a room full of his friends bragging about losing his virginity. His friends asked him to sit down and tell them the whole story. He replies "I can't sit down, my ass hurts." | C35: =IF(sample_1a!C35<>sample_1b!C35, sample_1a!C35 & " ≠ " & sample_1b!C35, "")
A36: 35 | B36: It Worked on the Other Side One night, a man and his wife were watching TV. It was about breast implants. The wife said, ”I wish I had bigger breast.” The man said, ”You don’t have to get silicone breasts, just wipe between your breast with toilet paper.” "How would that work?" asked the wife. The man said, "Well, you have been wiping your butt for 50 years and it's gotten bigger." | C36: =IF(sample_1a!C36<>sample_1b!C36, sample_1a!C36 & " ≠ " & sample_1b!C36, "")
A37: 36 | B37: A Guy takes his Friend to a bar A Guy takes his Friend to his favourite bar for the first time. They order a beer and someone shouts: "7"! Everyone started laughing. The Friend is visibly confused so the Guy explains: "Oh, right, you see, we've always been telling the same jokes over and over so we gave each a number, now instead of the joke you say the number and everyone knows what you mean". To prove it he says "24" and he gets a few chuckles. "That was a knock knock joke". The Friend decides to give it a try and says: "57". Everyone goes nuts, they all laugh like crazy. "Was it this funny?" he asks. Through tears the Guy says: "We haven't heard that one yet" | C37: =IF(sample_1a!C37<>sample_1b!C37, sample_1a!C37 & " ≠ " & sample_1b!C37, "")
A38: 37 | B38: I think I'm failing my marine biology class My grade is below C level. | C38: =IF(sample_1a!C38<>sample_1b!C38, sample_1a!C38 & " ≠ " & sample_1b!C38, "")
A39: 38 | B39: Post your best Chuck Norris Facts ! Chuck Norris once one a game of connect four in three moves ! | C39: =IF(sample_1a!C39<>sample_1b!C39, sample_1a!C39 & " ≠ " & sample_1b!C39, "")
A40: 39 | B40: There was a knock in my door "Who's there?" "Police" "Get out, I didn't call police, I called whores" "Your neighbors called us" "Let them fuck you then" | C40: =IF(sample_1a!C40<>sample_1b!C40, sample_1a!C40 & " ≠ " & sample_1b!C40, "") -> N ≠ CO | D40: CO
...

Sheet sample_2a
A1: id | B1: joke | C1: category_human
A2: 1 | B2: Helen Keller walks into a bar Then a table, then a chair. | C2: AP
A3: 2 | B3: You don't need a parachute To go skydiving. You need a parachute to go skydiving twice... | C3: N
A4: 3 | B4: Sherlock Holmes was keeping his eyes on a stranger. "Do you mind?" "I am a master of Me Stary" | C4: N
A5: 4 | B5: 4 gay necropheliacs are sitting around a bonfire. They had made this a weekly occurence, every week coming back and talking about the adventures they had that week. Jim and John were married. Trevor and Tom were also married. So week after week the 4 would come back to meet up and chat around the campfire. One week Jim and John didn't show up. Trevor: Where are Jim and John? Tom: Unfortunately, John died a few days ago. Trevor: Oh no, that's terrible! How did Jim take it? Tom: Up the ass. | C5: S
A6: 5 | B6: In the forest. A girl and a boy, both young, sensual, and full of hormones, walk through the dense forest. At the countryhouse lives girl's father, an old and conservative man, so boy got absolute zero pussy while staying there: but now, in this impenetrable grove, there is a perfect opportunity. "Hey, Anna, do you want to screw for a bit?" "Sure", girl exitedly answers. The boy clears out a bit of undergrowth and starts pulling down his pants; the girl is already undressed. Suddenly, he feels a terrible urge to pee. "Sorry, I gotta take a leak, will be back in thirty seconds!" "No, Ivan, I'm naked and don't you know that Fast Gonzales lives in these woods? As soon as you are gonna he is gonna, you know." "Ok, sure, I'll just turn my back and pee here." "He is named Fast Gonzales not for nothing!" "Seriously? Alright, I'll turn my back, pee, and stick a finger in your cunt so that he doesn't start anything funny." The guy turns his back and sticks a finger into fast Gonzales' asshole. | C6: G
A7: 6 | B7: What has 4 letters, sometimes 9 letters, but never has 5 letters. hint hint: don't overthink | C7: N
A8: 7 | B8: What does the Cincinnati gorilla story tell us? It's the first time that black-on-black crime made national (even international) news. | C8: RE
A9: 8 | B9: A rope walks into a bar The bartender says "we don't serve your kind here." The rope leaves and cuts the top of his hair. He comes back the next day and the bartender says, "are you that rope I kicked outta here yesterday?" The rope says, "I'm a frayed knot." Then he gets shot in the face. | C9: N
A10: 9 | B10: What do you call a Greenpeace streaker? Free Willy | C10: N
A11: 10 | B11: Why was the clock always so itchy? Because it had tiks | C11: N
A12: 11 | B12: Three men are on a boat Three men are on a boat and have cigarettes but nothing to light them with. So one man throws a cigarette off the boat and the boat becomes a cigarette lighter. | C12: N
A13: 12 | B13: At times I hide my girlfriends asthma inhaler just to make her scream “give it to me, give it to me,” so that my neighbour thinks I have a great sex life. | C13: G
... A101: 100 | B101: There is a better man inside of Trump... And Putin has a large penis. | C101: PI

Sheet sample_2b
A1: id | B1: joke | C1: category_human
A2: 1 | B2: Helen Keller walks into a bar Then a table, then a chair. | C2: N
A3: 2 | B3: You don't need a parachute To go skydiving. You need a parachute to go skydiving twice... | C3: N
A4: 3 | B4: Sherlock Holmes was keeping his eyes on a stranger. "Do you mind?" "I am a master of Me Stary" | C4: N
A5: 4 | B5: 4 gay necropheliacs are sitting around a bonfire. They had made this a weekly occurence, every week coming back and talking about the adventures they had that week. Jim and John were married. Trevor and Tom were also married. So week after week the 4 would come back to meet up and chat around the campfire. One week Jim and John didn't show up. Trevor: Where are Jim and John? Tom: Unfortunately, John died a few days ago. Trevor: Oh no, that's terrible! How did Jim take it? Tom: Up the ass. | C5: S
A6: 5 | B6: In the forest. A girl and a boy, both young, sensual, and full of hormones, walk through the dense forest. At the countryhouse lives girl's father, an old and conservative man, so boy got absolute zero pussy while staying there: but now, in this impenetrable grove, there is a perfect opportunity. "Hey, Anna, do you want to screw for a bit?" "Sure", girl exitedly answers. The boy clears out a bit of undergrowth and starts pulling down his pants; the girl is already undressed. Suddenly, he feels a terrible urge to pee. "Sorry, I gotta take a leak, will be back in thirty seconds!" "No, Ivan, I'm naked and don't you know that Fast Gonzales lives in these woods? As soon as you are gonna he is gonna, you know." "Ok, sure, I'll just turn my back and pee here." "He is named Fast Gonzales not for nothing!" "Seriously? Alright, I'll turn my back, pee, and stick a finger in your cunt so that he doesn't start anything funny." The guy turns his back and sticks a finger into fast Gonzales' asshole. | C6: N
A7: 6 | B7: What has 4 letters, sometimes 9 letters, but never has 5 letters. hint hint: don't overthink | C7: N
A8: 7 | B8: What does the Cincinnati gorilla story tell us? It's the first time that black-on-black crime made national (even international) news. | C8: RE
A9: 8 | B9: A rope walks into a bar The bartender says "we don't serve your kind here." The rope leaves and cuts the top of his hair. He comes back the next day and the bartender says, "are you that rope I kicked outta here yesterday?" The rope says, "I'm a frayed knot." Then he gets shot in the face. | C9: N
A10: 9 | B10: What do you call a Greenpeace streaker? Free Willy | C10: PI
A11: 10 | B11: Why was the clock always so itchy? Because it had tiks | C11: N
A12: 11 | B12: Three men are on a boat Three men are on a boat and have cigarettes but nothing to light them with. So one man throws a cigarette off the boat and the boat becomes a cigarette lighter. | C12: N
A13: 12 | B13: At times I hide my girlfriends asthma inhaler just to make her scream “give it to me, give it to me,” so that my neighbour thinks I have a great sex life. | C13: AP
... A21: 20 | B21: Why did the dog cross the road? To catch his bark (my brother made up this joke when he was really young) | C21: N
A22: 21 | B22: I've been trying to find out what "flabby" means. But I couldn't see any definition.
A23: 22 | B23: A patient rushes to a hospital. Patient: NURSE I NEED A DOCTOR IMMEDIATELY!!! I'M HAVING A HUGE ISSUE RIGHT NOW. The nurse sees the distress in the patients eyes and calls over the doctor. Doctor: What seems to be the problem? Patient: I don't know doc. I woke up this morning and I'm half deaf. I only hear half of everything. Doctor: I'm sorry but that's not possible. It is just not possible to hear half of everything. Patient: No doc, I'm serious. I only hear half of everything. Doctor: Ok. We can check this out then. Repeat after me: fourty four Patient: Twenty two | C23: AP
A24: 23 | B24: How many snowboarders does it take to screw in a lightbulb? Only 3: One to screw it in, another to film it, and a last one to say "sick turns brah!" | C24: CO
A25: 24 | B25: Why would Donald Trump want to lose the election? Winning means he'd need to live in a smaller house in a black neighborhood | C25: PI
A26: 25 | B26: The German kid asks the math teacher... What’s 4 + 5? The math teacher responds that it’s nine but when the teacher grades the homework he hadn’t written anything. | C26: RE
A27: 26 | B27: The only reason why humans start wars is because we have time to kill | C27: N
A28: 27 | B28: What's the most searched word on Bing? Google | C28: N
A29: 28 | B29: What do you have if you've got a green ball in each hand? The Hulk's undivided attention. | C29: N
A30: 29 | B30: A man of the cloth was touring the country preaching. He stopped at an unfamiliar hotel chain for the night and asked for a room. He took his room key and told the young woman working behind the front desk, "There better be bibles in the nightstand and the porn channels disabled." She looked shocked and responded "No! They're normal you pervert!" | C30: RE
A31: 30 | B31: What do Rick and Morty season 3 and my girlfriend have in common? They both don't exist | C31: N
A32: 31 | B32: What is the warmest period in the history of the world's climate called? Climax. | C32: N
A33: 32 | B33: A man goes to the doctor. Man: "Doctor, I have this problem." Doctor: "What is the issue?" Man: "Everytime I'm driving with my friends, we go through this tunnel, and I just can't control myself. I freak right out." Doctor: "Sounds like you have Carpool Tunnel Syndrome." | C33: M
A34: 33 | B34: Where are the best elephant dentists? Tuscaloosa. | C34: N
... A101: 100 | B101: There is a better man inside of Trump... And Putin has a large penis. | C101: PI

Sheet conflict_2
A1: M | B1: joke | C1: Conflict | D1: Adjudication
A2: 1 | B2: Helen Keller walks into a bar Then a table, then a chair. | C2: =IF(sample_2a!C2<>sample_2b!C2, sample_2a!C2 & " ≠ " & sample_2b!C2, "") -> AP ≠ N | D2: AP
A3: 2 | B3: You don't need a parachute To go skydiving. You need a parachute to go skydiving twice... | C3: =IF(sample_2a!C3<>sample_2b!C3, sample_2a!C3 & " ≠ " & sample_2b!C3, "")
A4: 3 | B4: Sherlock Holmes was keeping his eyes on a stranger. "Do you mind?" "I am a master of Me Stary" | C4: =IF(sample_2a!C4<>sample_2b!C4, sample_2a!C4 & " ≠ " & sample_2b!C4, "")
A5: 4 | B5: 4 gay necropheliacs are sitting around a bonfire. They had made this a weekly occurence, every week coming back and talking about the adventures they had that week. Jim and John were married. Trevor and Tom were also married. So week after week the 4 would come back to meet up and chat around the campfire. One week Jim and John didn't show up. Trevor: Where are Jim and John? Tom: Unfortunately, John died a few days ago. Trevor: Oh no, that's terrible! How did Jim take it? Tom: Up the ass. | C5: =IF(sample_2a!C5<>sample_2b!C5, sample_2a!C5 & " ≠ " & sample_2b!C5, "")
A6: 5 | B6: In the forest. A girl and a boy, both young, sensual, and full of hormones, walk through the dense forest. At the countryhouse lives girl's father, an old and conservative man, so boy got absolute zero pussy while staying there: but now, in this impenetrable grove, there is a perfect opportunity. "Hey, Anna, do you want to screw for a bit?" "Sure", girl exitedly answers. The boy clears out a bit of undergrowth and starts pulling down his pants; the girl is already undressed. Suddenly, he feels a terrible urge to pee. "Sorry, I gotta take a leak, will be back in thirty seconds!" "No, Ivan, I'm naked and don't you know that Fast Gonzales lives in these woods? As soon as you are gonna he is gonna, you know." "Ok, sure, I'll just turn my back and pee here." "He is named Fast Gonzales not for nothing!" "Seriously? Alright, I'll turn my back, pee, and stick a finger in your cunt so that he doesn't start anything funny." The guy turns his back and sticks a finger into fast Gonzales' asshole. | C6: =IF(sample_2a!C6<>sample_2b!C6, sample_2a!C6 & " ≠ " & sample_2b!C6, "") -> G ≠ N | D6: N
A7: 6 | B7: What has 4 letters, sometimes 9 letters, but never has 5 letters. hint hint: don't overthink | C7: =IF(sample_2a!C7<>sample_2b!C7, sample_2a!C7 & " ≠ " & sample_2b!C7, "")
A8: 7 | B8: What does the Cincinnati gorilla story tell us? It's the first time that black-on-black crime made national (even international) news. | C8: =IF(sample_2a!C8<>sample_2b!C8, sample_2a!C8 & " ≠ " & sample_2b!C8, "")
A9: 8 | B9: A rope walks into a bar The bartender says "we don't serve your kind here." The rope leaves and cuts the top of his hair. He comes back the next day and the bartender says, "are you that rope I kicked outta here yesterday?" The rope says, "I'm a frayed knot." Then he gets shot in the face. | C9: =IF(sample_2a!C9<>sample_2b!C9, sample_2a!C9 & " ≠ " & sample_2b!C9, "")
A10: 9 | B10: What do you call a Greenpeace streaker? Free Willy | C10: =IF(sample_2a!C10<>sample_2b!C10, sample_2a!C10 & " ≠ " & sample_2b!C10, "") -> N ≠ PI | D10: PI
A11: 10 | B11: Why was the clock always so itchy? Because it had tiks | C11: =IF(sample_2a!C11<>sample_2b!C11, sample_2a!C11 & " ≠ " & sample_2b!C11, "")
A12: 11 | B12: Three men are on a boat Three men are on a boat and have cigarettes but nothing to light them with. So one man throws a cigarette off the boat and the boat becomes a cigarette lighter. | C12: =IF(sample_2a!C12<>sample_2b!C12, sample_2a!C12 & " ≠ " & sample_2b!C12, "")
A13: 12 | B13: At times I hide my girlfriends asthma inhaler just to make her scream “give it to me, give it to me,” so that my neighbour thinks I have a great sex life. | C13: =IF(sample_2a!C13<>sample_2b!C13, sample_2a!C13 & " ≠ " & sample_2b!C13, "") -> G ≠ AP | D13: AP
A14: 13 | B14: What’s the difference between a truck load of tennis balls and a truck load of dead babies? You can’t unload tennis balls with a pitchfork. | C14: =IF(sample_2a!C14<>sample_2b!C14, sample_2a!C14 & " ≠ " & sample_2b!C14, "")
A15: 14 | B15: A coworker was telling us how stingy Asians are with their money. "It's just their genes," he argued earnestly, "they were just born that way." Not one to let a racial slur slide, especially at a politically correct workplace, I was quick to correct him. "Steve, you can't say things like that. Even if you are mad at someone, two Wongs don't make a Wright." | C15: =IF(sample_2a!C15<>sample_2b!C15, sample_2a!C15 & " ≠ " & sample_2b!C15, "")
A16: 15 | B16: A Japanese man, two Italians, an elf, and a woman in armor walk into an Ice cream parlor. The vendor looks at the Japanese man and says, “are those cosplayers?” He responds with “no, these are my children.” One of the Italians said “We helped him-a program an upcoming-a game so that only one person can-a turn into a peach when they touch-a the crown.” “Everyone else will receive ten units of their respective currency.” The armored woman said. The elf silently took two blue rupees from his messenger bag. | C16: =IF(sample_2a!C16<>sample_2b!C16, sample_2a!C16 & " ≠ " & sample_2b!C16, "") -> RE ≠ N | D16: N
A17: 16 | B17: I was stacking rusty blocks yesterday and got poked I went to the doctor today and he told me i had tetris | C17: =IF(sample_2a!C17<>sample_2b!C17, sample_2a!C17 & " ≠ " & sample_2b!C17, "")
A18: 17 | B18: Infinity loop a woman walks into her hypnotherapists office and says " Doctor, I have been loyal to my husband for 12 years but, last night I broke that loyalty and had an affair. I just want you to make me forget it happened". The Doctor said " Not again" | C18: =IF(sample_2a!C18<>sample_2b!C18, sample_2a!C18 & " ≠ " & sample_2b!C18, "")
A19: 18 | B19: a simple one **what do you call a team of** **religious mutants?** **A-men** | C19: =IF(sample_2a!C19<>sample_2b!C19, sample_2a!C19 & " ≠ " & sample_2b!C19, "") -> R ≠ G | D19: R
A20: 19 | B20: Wonder woman Superman was kinda bored so he just started flying around looking for something to do. He's flying over Wonder Woman's house and sees her bedroom window is open. He stops for a glimpse and sees her lying on her bed naked. She's lying there and squirming around looking real hot. Superman was getting turned on looking at her so he decides what the hell, I can just fly in real quick, give her the ole' in-out and be out of there before she even knows what hit her. After all he is Superman. So, in he goes, wham-bam and he's out of there. Wonder Woman knew something happened and says, "What was that?" The invisible man says, "I don't know but, damn, is my ass sore." | C20: =IF(sample_2a!C20<>sample_2b!C20, sample_2a!C20 & " ≠ " & sample_2b!C20, "") -> G ≠ N | D20: N
A21: 20 | B21: Why did the dog cross the road? To catch his bark (my brother made up this joke when he was really young) | C21: =IF(sample_2a!C21<>sample_2b!C21, sample_2a!C21 & " ≠ " & sample_2b!C21, "")
A22: 21 | B22: I've been trying to find out what "flabby" means. But I couldn't see any definition. | C22: =IF(sample_2a!C22<>sample_2b!C22, sample_2a!C22 & " ≠ " & sample_2b!C22, "") -> AP ≠ | D22: AP
A23: 22 | B23: A patient rushes to a hospital. Patient: NURSE I NEED A DOCTOR IMMEDIATELY!!! I'M HAVING A HUGE ISSUE RIGHT NOW. The nurse sees the distress in the patients eyes and calls over the doctor. Doctor: What seems to be the problem? Patient: I don't know doc. I woke up this morning and I'm half deaf. I only hear half of everything. Doctor: I'm sorry but that's not possible. It is just not possible to hear half of everything. Patient: No doc, I'm serious. I only hear half of everything. Doctor: Ok. We can check this out then. Repeat after me: fourty four Patient: Twenty two | C23: =IF(sample_2a!C23<>sample_2b!C23, sample_2a!C23 & " ≠ " & sample_2b!C23, "") -> N ≠ AP | D23: AP
A24: 23 | B24: How many snowboarders does it take to screw in a lightbulb? Only 3: One to screw it in, another to film it, and a last one to say "sick turns brah!" | C24: =IF(sample_2a!C24<>sample_2b!C24, sample_2a!C24 & " ≠ " & sample_2b!C24, "") -> N ≠ CO | D24: CO
A25: 24 | B25: Why would Donald Trump want to lose the election? Winning means he'd need to live in a smaller house in a black neighborhood | C25: =IF(sample_2a!C25<>sample_2b!C25, sample_2a!C25 & " ≠ " & sample_2b!C25, "") -> RE ≠ PI | D25: N
A26: 25 | B26: The German kid asks the math teacher... What’s 4 + 5? The math teacher responds that it’s nine but when the teacher grades the homework he hadn’t written anything. | C26: =IF(sample_2a!C26<>sample_2b!C26, sample_2a!C26 & " ≠ " & sample_2b!C26, "")
A27: 26 | B27: The only reason why humans start wars is because we have time to kill | C27: =IF(sample_2a!C27<>sample_2b!C27, sample_2a!C27 & " ≠ " & sample_2b!C27, "")
A28: 27 | B28: What's the most searched word on Bing? Google | C28: =IF(sample_2a!C28<>sample_2b!C28, sample_2a!C28 & " ≠ " & sample_2b!C28, "")
A29: 28 | B29: What do you have if you've got a green ball in each hand? The Hulk's undivided attention. | C29: =IF(sample_2a!C29<>sample_2b!C29, sample_2a!C29 & " ≠ " & sample_2b!C29, "")
A30: 29 | B30: A man of the cloth was touring the country preaching. He stopped at an unfamiliar hotel chain for the night and asked for a room. He took his room key and told the young woman working behind the front desk, "There better be bibles in the nightstand and the porn channels disabled." She looked shocked and responded "No! They're normal you pervert!" | C30: =IF(sample_2a!C30<>sample_2b!C30, sample_2a!C30 & " ≠ " & sample_2b!C30, "") -> N ≠ RE | D30: N
A31: 30 | B31: What do Rick and Morty season 3 and my girlfriend have in common? They both don't exist | C31: =IF(sample_2a!C31<>sample_2b!C31, sample_2a!C31 & " ≠ " & sample_2b!C31, "")
A32: 31 | B32: What is the warmest period in the history of the world's climate called? Climax. | C32: =IF(sample_2a!C32<>sample_2b!C32, sample_2a!C32 & " ≠ " & sample_2b!C32, "")
A33: 32 | B33: A man goes to the doctor. Man: "Doctor, I have this problem." Doctor: "What is the issue?" Man: "Everytime I'm driving with my friends, we go through this tunnel, and I just can't control myself. I freak right out." Doctor: "Sounds like you have Carpool Tunnel Syndrome." | C33: =IF(sample_2a!C33<>sample_2b!C33, sample_2a!C33 & " ≠ " & sample_2b!C33, "") -> N ≠ M | D33: M
A34: 33 | B34: Where are the best elephant dentists? Tuscaloosa. | C34: =IF(sample_2a!C34<>sample_2b!C34, sample_2a!C34 & " ≠ " & sample_2b!C34, "")
A35: 34 | B35: I always park in handicapped spaces at the hospital Just to test their patients | C35: =IF(sample_2a!C35<>sample_2b!C35, sample_2a!C35 & " ≠ " & sample_2b!C35, "")
A36: 35 | B36: Four guys were working on a construction site They were talking about life and one of them misstepped on the scaffolding, fell from the fourth floor, hit his head and died on the spot. His friends were all shaken. They called 911, took all legal actions they should and their friend's body was removed. One of them, noticing they faced a problem, said: "Who's gonna tell his wife about this? "I'm not doing it!" Said another one. "Neither am I! You should do it!" Said the other. "I'm not going!" Said the first one. "Well, you're the most educated of us. It's better that you go, any other of us could deliver the news in a wrong way and give her a heart attack." Said the second guy. "All right, all right. I know how to do this." Said the first one and left to tell the new widow the sad news. The other two remained to close up the site and tidy up the place. A few minutes later the first guy comes back, six-pack of beer under his arm, drinking a cold one. "What the hell? Didn't you go tell the widow about our friend?" Said one guy. "I did exactly that." He said, taking another gulp. "And why are you back here with a six-pack?" "Well, I went to her house and she was at the door. I asked her: 'Aren't you the widow who was married to that guy who died on the construction site?' 'No, I'm not' she said. Then I said: 'Wanna bet a six-pack on it?'" *Sorry if this has been posted before. My father told me this one and I wanted to share.* | C36: =IF(sample_2a!C36<>sample_2b!C36, sample_2a!C36 & " ≠ " & sample_2b!C36, "")
A37: 36 | B37: The ass was phat. It was so phat it was alkaline. | C37: =IF(sample_2a!C37<>sample_2b!C37, sample_2a!C37 & " ≠ " & sample_2b!C37, "") -> N ≠ AP | D37: AP
A38: 37 | B38: What's the difference between Big Ben and the Queen of England? One is inhuman, intricately decorated, and exists only to mark the passage of time. &#x200B; The other one's a clock. | C38: =IF(sample_2a!C38<>sample_2b!C38, sample_2a!C38 & " ≠ " & sample_2b!C38, "") -> N ≠ PI | D38: PI
A39: 38 | B39: What do you call a monkey in a minefield? A baBOOM | C39: =IF(sample_2a!C39<>sample_2b!C39, sample_2a!C39 & " ≠ " & sample_2b!C39, "")
A40: 39 | B40: When I was a child, I loved astronomy and I actually saw Orion's belt many times. My Dad's nickname was Orion and he used to beat the shit out of me because I didn't like sports. | C40: =IF(sample_2a!C40<>sample_2b!C40, sample_2a!C40 & " ≠ " & sample_2b!C40, "")
...

Sheet sample_3a
A1: id | B1: joke | C1: category_human
A2: 1 | B2: Ironman walked up to Thor Ironman walked up to Thor and said "You have an ugly tie" Thor replied back "Respect my A-Thor-A-Tie!!!!" | C2: N
A3: 2 | B3: How do you manage to stop an aircraft from crashing? You buck up and man the controls, *plane* and simple. | C3: N
A4: 3 | B4: When people go underwater in movies, I like to hold my breath to see if I would have survived the same situation... Almost died in Finding Nemo | C4: N
A5: 4 | B5: I saw a refrigerator call a cab once Guess he was tired of running. | C5: N
A6: 5 | B6: Knight vs dragon A knight is fighting a dragon. He cuts its head, but the dragon grows two new heads. The knight cuts them, but the dragon grows 4 heads. The knight cuts them, the dragon grows 8 heads. The knight cuts them, the dragon grows 16 heads. The knight cuts them, the dragon grows 32 heads. The knight cuts them, the dragon grows 64 heads. The knight cuts them, the dragon grows 128 heads. The knight cuts them and the dragon is finally dead. It was an 8-bit dragon. | C6: N
A7: 6 | B7: Why can't miss piggy count to 100? She has a frog in her throat at 69 | C7: N
A8: 7 | B8: Why was the dolphin sad? Because it didn't know it's porpoise in life. Thank you. Thank you. | C8: N
A9: 8 | B9: What do you call a gay Asian guy? A Caucasian | C9: RE
A10: 9 | B10: The man who invented the Hokey Cokey died recently aged 93. At his funeral they went to put him in his coffin. They put his left leg in and then the fucking trouble started. | C10: N
A11: 10 | B11: What do you call it when someone impersonates himself on reddit? This guy this guys. | C11: N
A12: 11 | B12: Knock knock joke in China a: Knock knock b: Whose there? a: Yep! Its me, your buddy Hu! | C12: RE
A13: 12 | B13: What is your birthstone? Mine is rock bottom. | C13: N
... A101: 100 | B101: After arriving home from Bring Your Kid to Work day My son turned to me and said, “you have the most boring job ever. All you do is put people to sleep all day”...I’m an anesthesiologist | C101: CO

Sheet sample_3b
A1: id | B1: joke | C1: category_human
A2: 1 | B2: Ironman walked up to Thor Ironman walked up to Thor and said "You have an ugly tie" Thor replied back "Respect my A-Thor-A-Tie!!!!" | C2: N
A3: 2 | B3: How do you manage to stop an aircraft from crashing? You buck up and man the controls, *plane* and simple. | C3: N
A4: 3 | B4: When people go underwater in movies, I like to hold my breath to see if I would have survived the same situation... Almost died in Finding Nemo | C4: N
A5: 4 | B5: I saw a refrigerator call a cab once Guess he was tired of running. | C5: N
A6: 5 | B6: Knight vs dragon A knight is fighting a dragon. He cuts its head, but the dragon grows two new heads. The knight cuts them, but the dragon grows 4 heads. The knight cuts them, the dragon grows 8 heads. The knight cuts them, the dragon grows 16 heads. The knight cuts them, the dragon grows 32 heads. The knight cuts them, the dragon grows 64 heads. The knight cuts them, the dragon grows 128 heads. The knight cuts them and the dragon is finally dead. It was an 8-bit dragon. | C6: N
A7: 6 | B7: Why can't miss piggy count to 100? She has a frog in her throat at 69 | C7: G
A8: 7 | B8: Why was the dolphin sad? Because it didn't know it's porpoise in life. Thank you. Thank you. | C8: N
A9: 8 | B9: What do you call a gay Asian guy? A Caucasian | C9: S, RE
A10: 9 | B10: The man who invented the Hokey Cokey died recently aged 93. At his funeral they went to put him in his coffin. They put his left leg in and then the fucking trouble started. | C10: N
A11: 10 | B11: What do you call it when someone impersonates himself on reddit? This guy this guys. | C11: N
A12: 11 | B12: Knock knock joke in China a: Knock knock b: Whose there? a: Yep! Its me, your buddy Hu! | C12: RE
A13: 12 | B13: What is your birthstone? Mine is rock bottom. | C13: M
A14: 13 | B14: Old genie joke... Three men find themselves stranded on a deserted island. After several years, despite their differences, they become close friends out of necessity. One day, they find an old lamp. On rubbing it clean, they release a genie who grants them each one wish. "I wish to return to my old life!" Two of the men shout, disappearing in a puff of smoke. The third man, a little slow, looks around at the empty island. Overcome by loneliness, he mutters, "I wish my friends were here."
A15: 14 | B15: Potentially funny joke about a bed I just haven't made it up yet. | C15: N
A16: 15 | B16: As a vet, attention to detail is vital. However, attention to de rest of de animal is important too. | C16: CO
A17: 16 | B17: Why did the chicken cross the road To get to the other side lololol 😂😂😂 | C17: N
A18: 17 | B18: Police officers have been playing Pokemon Go a lot longer than the rest y'all have... 'Gotta catch Jamal' | C18: RE, CO
A19: 18 | B19: What's a skeleton's favorite insturment a trom**BONE** | C19: N
A20: 19 | B20: How do you know the hipster knows ju jitsu? He knew that move before you did. | C20: N
A21: 20 | B21: A man wants to jump off a bridge... (This joke is courtesy of Emo Philips) I was walking across a bridge one day, and I saw a man standing on the edge, about to jump off. So I ran over and said "Stop! Don't do it!" "Why shouldn't I?" he said. "Well, there's so much to live for!" "Like what?" "Well... are you religious?" He said yes. I said, "Me too! Are you Christian or Buddhist?" "Christian." "Me too! Are you Catholic or Protestant? "Protestant." "Me too! Are you Episcopalian or Baptist?" "Baptist" "Wow! Me too! Are you Baptist Church of God or Baptist Church of the Lord?" "Baptist Church of God!" "Me too! Are you original Baptist Church of God, or are you reformed Baptist Church of God?" "Reformed Baptist Church of God!" "Me too! Are you Reformed Baptist Church of God, reformation of 1879, or Reformed Baptist Church of God, reformation of 1915?" He said, "Reformed Baptist Church of God, reformation of 1915!" I said, "Die, heretic scum", and pushed him off. | C21: R
A22: 21 | B22: So 6ix9ine could be facing life in prison Maybe a mumble rapper will finally finish a sentence | C22: CO
A23: 22 | B23: So I went to the doctor to check on my exams. He asked me: - What’s you sign? Me: - Cancer Doctor: - Now that’s a coincidence. | C23: CO
A24: 23 | B24: Where is the safest place to be shopping during an earthquake? A stationary store. | C24: N
A25: 24 | B25: Just said Hi to this guy on the plane and everyone freaked out Apparently his name was Jack | C25: N
A26: 25 | B26: Why does Donald Trump secretly want to lose the election? To Make America Great Again | C26: PI
... A54: 53 | B54: At McDonald's Employee: Are you going to eat here? Customer: Well, now that you said it... I'll go to burger king! | C54: N
A55: 54 | B55: I don't know if digital anal sex toys would be legal.... But iAnal
A56: 55 | B56: An Englishman, Scotsman and an Irishman trying to get into the Olympics with no tickets The Englishman found a large wooden pole lying on the ground near him. He picked it up, put it under his arm, walked in the gate and said 'Bentley, England, pole vaulting' and they let him in. The Scotsman picked up a manhole cover, put it under his arm, walked in the gate and said 'McGregor, Scotland, discus' and they let him in. The Irish man picked up a roll of barbed wire, put it under his arm, walked in the gate and said 'Murphy, Ireland, fencing.' | C56: RE, CO
A57: 56 | B57: What do you call a typo on a tombstone A grave mistake. | C57: N
A58: 57 | B58: Why do they put a cock on a weather vane? Because if they put a cunt on there, the wind would blow right through it. | C58: G
A59: 58 | B59: How do you get away with murder? You kill a Saudi dissident. &#x200B; Were you expecting a longer punchline? | C59: RE, R
A60: 59 | B60: Four college students have been out partying for a night before an exam. The next morning, they wake up and realize they're late, so as they make their way to the exam, they come up with excuses to make for the professor. By the time they arrive the exam is almost over, so they head over to the professor to ask if they can take it the next day. They tell him they tried their best to come on time, but their tire blew out and it took too long to replace it. The professor tells them, "Don't worry about it. You can take it today and, since there's almost no time left, you only have to answer one question. If you get it right, I'll give you an A on the test. One thing, though- you all have to be in separate rooms." The students, thinking this is even better than they thought, excitedly go to their rooms, take their seats and look at the question: Which tire blew out? | C60: N
A61: 60 | B61: Thank you banks Thank you banks for the student loans, car loans and mortgages, which helped me survive my life. I don't know if I can ever repay you. | C61: N
A62: 61 | B62: What do you call an Indian who marries out of cast? Outcast | C62: RE
A63: 62 | B63: What is your best joke that involves soup? I need some help. Jokes just need to involve soup. Does not matter what kind of soup or what is being done with the soup. | C63: N
A64: 63 | B64: My ex left me two years ago because I was an insensitive bastard. I still don't think about her to this day. | C64: N
A65: 64 | B65: Joe fails his third test of the semester. His teacher meets with his mother after school that day and she agrees to talk to him about learning disabilities and getting extra help. After they meet, Joe is shaken. "I'm a slow learner?" thinks Joe. "Wow. You learn something new every couple of days." | C65: AP
A66: 65 | B66: I'm not a mute and that's more than some people can say. | C66: AP
A67: 66 | B67: What do you call a waffle that you dropped at the beach? sandy Eggo | C67: N
...

Sheet conflict_3
A1: id | B1: joke | C1: Conflict | D1: Adjudication
A2: 1 | B2: Ironman walked up to Thor Ironman walked up to Thor and said "You have an ugly tie" Thor replied back "Respect my A-Thor-A-Tie!!!!" | C2: =IF(sample_3a!C2<>sample_3b!C2, sample_3a!C2 & " ≠ " & sample_3b!C2, "")
A3: 2 | B3: How do you manage to stop an aircraft from crashing? You buck up and man the controls, *plane* and simple. | C3: =IF(sample_3a!C3<>sample_3b!C3, sample_3a!C3 & " ≠ " & sample_3b!C3, "")
A4: 3 | B4: When people go underwater in movies, I like to hold my breath to see if I would have survived the same situation... Almost died in Finding Nemo | C4: =IF(sample_3a!C4<>sample_3b!C4, sample_3a!C4 & " ≠ " & sample_3b!C4, "")
A5: 4 | B5: I saw a refrigerator call a cab once Guess he was tired of running. | C5: =IF(sample_3a!C5<>sample_3b!C5, sample_3a!C5 & " ≠ " & sample_3b!C5, "")
A6: 5 | B6: Knight vs dragon A knight is fighting a dragon. He cuts its head, but the dragon grows two new heads. The knight cuts them, but the dragon grows 4 heads. The knight cuts them, the dragon grows 8 heads. The knight cuts them, the dragon grows 16 heads. The knight cuts them, the dragon grows 32 heads. The knight cuts them, the dragon grows 64 heads. The knight cuts them, the dragon grows 128 heads. The knight cuts them and the dragon is finally dead. It was an 8-bit dragon. | C6: =IF(sample_3a!C6<>sample_3b!C6, sample_3a!C6 & " ≠ " & sample_3b!C6, "")
A7: 6 | B7: Why can't miss piggy count to 100? She has a frog in her throat at 69 | C7: =IF(sample_3a!C7<>sample_3b!C7, sample_3a!C7 & " ≠ " & sample_3b!C7, "") -> N ≠ G | D7: N
A8: 7 | B8: Why was the dolphin sad? Because it didn't know it's porpoise in life. Thank you. Thank you. | C8: =IF(sample_3a!C8<>sample_3b!C8, sample_3a!C8 & " ≠ " & sample_3b!C8, "")
A9: 8 | B9: What do you call a gay Asian guy? A Caucasian | C9: =IF(sample_3a!C9<>sample_3b!C9, sample_3a!C9 & " ≠ " & sample_3b!C9, "") -> RE ≠ S, RE | D9: S, RE
A10: 9 | B10: The man who invented the Hokey Cokey died recently aged 93. At his funeral they went to put him in his coffin. They put his left leg in and then the fucking trouble started. | C10: =IF(sample_3a!C10<>sample_3b!C10, sample_3a!C10 & " ≠ " & sample_3b!C10, "")
A11: 10 | B11: What do you call it when someone impersonates himself on reddit? This guy this guys. | C11: =IF(sample_3a!C11<>sample_3b!C11, sample_3a!C11 & " ≠ " & sample_3b!C11, "")
A12: 11 | B12: Knock knock joke in China a: Knock knock b: Whose there? a: Yep! Its me, your buddy Hu! | C12: =IF(sample_3a!C12<>sample_3b!C12, sample_3a!C12 & " ≠ " & sample_3b!C12, "")
A13: 12 | B13: What is your birthstone? Mine is rock bottom. | C13: =IF(sample_3a!C13<>sample_3b!C13, sample_3a!C13 & " ≠ " & sample_3b!C13, "") -> N ≠ M | D13: M
